Workbook

Sheet Raw_Data
A1: A/C | B1: Ward | C1: Facility | D1: % of planned fixed sessions held June 2025 | E1: % of planned fixed sessions held July 2025 | F1: % of planned fixed sessions held August 2025 | G1: % of planned fixed sessions held September 2025 | H1: % of planned fixed sessions held October 2025 | I1: % of planned fixed sessions held November 2025 | J1: % of planned fixed sessions held December 2025 | K1: % of planned fixed sessions held January 2026 | L1: % of planned fixed sessions held February 2026 | M1: % of planned fixed sessions held March 2026 | N1: % of planned fixed sessions held April 2026 | O1: % of planned fixed sessions held May 2026 | P1: % of Planned outreach sessions held June 2025 | Q1: % of Planned outreach sessions held July 2025 | R1: % of Planned outreach sessions held August 2025 | S1: % of Planned outreach sessions held September 2025 | T1: % of Planned outreach sessions held October 2025 | U1: % of Planned outreach sessions held November 2025 | V1: % of Planned outreach sessions held December 2025 | W1: % of Planned outreach sessions held January 2026 | X1: % of Planned outreach sessions held February 2026 | Y1: % of Planned outreach sessions held March 2026 | Z1: % of Planned outreach sessions held April 2026 | AA1: % of Planned outreach sessions held May 2026 | AB1: Penta. 1 given June 2025 | AC1: Penta. 1 given July 2025 | AD1: Penta. 1 given August 2025 | AE1: Penta. 1 given September 2025 | AF1: Penta. 1 given October 2025 | AG1: Penta. 1 given November 2025 | AH1: Penta. 1 given December 2025 | AI1: Penta. 1 given January 2026 | AJ1: Penta. 1 given February 2026 | AK1: Penta. 1 given March 2026 | AL1: Penta. 1 given April 2026 | AM1: Penta. 1 given May 2026 | AN1: Penta 3 given June 2025 | AO1: Penta 3 given July 2025 | AP1: Penta 3 given August 2025 | AQ1: Penta 3 given September 2025 | AR1: Penta 3 given October 2025 | AS1: Penta 3 given November 2025 | AT1: Penta 3 given December 2025 | AU1: Penta 3 given January 2026 | AV1: Penta 3 given February 2026 | AW1: Penta 3 given March 2026 | AX1: Penta 3 given April 2026 | AY1: Penta 3 given May 2026 | AZ1: ANC 1st Visit June 2025 | BA1: ANC 1st Visit July 2025 | BB1: ANC 1st Visit August 2025 | BC1: ANC 1st Visit September 2025 | BD1: ANC 1st Visit October 2025 | BE1: ANC 1st Visit November 2025 | BF1: ANC 1st Visit December 2025 | BG1: ANC 1st Visit January 2026 | BH1: ANC 1st Visit February 2026 | BI1: ANC 1st Visit March 2026 | BJ1: ANC 1st Visit April 2026 | BK1: ANC 1st Visit May 2026 | BL1: ANC 4th visit June 2025 | BM1: ANC 4th visit July 2025 | BN1: ANC 4th visit August 2025 | BO1: ANC 4th visit September 2025 | BP1: ANC 4th visit October 2025 | BQ1: ANC 4th visit November 2025 | BR1: ANC 4th visit December 2025 | BS1: ANC 4th visit January 2026 | BT1: ANC 4th visit February 2026 | BU1: ANC 4th visit March 2026 | BV1: ANC 4th visit April 2026 | BW1: ANC 4th visit May 2026 | BX1: ANC 8th Visit June 2025 | BY1: ANC 8th Visit July 2025 | BZ1: ANC 8th Visit August 2025 | CA1: ANC 8th Visit September 2025 | CB1: ANC 8th Visit October 2025 | CC1: ANC 8th Visit November 2025 | CD1: ANC 8th Visit December 2025 | CE1: ANC 8th Visit January 2026 | CF1: ANC 8th Visit February 2026 | CG1: ANC 8th Visit March 2026 | CH1: ANC 8th Visit April 2026 | CI1: ANC 8th Visit May 2026
A2: Abuja Municipal Area Council | B2: Gui Ward | C2: 063 Nigeria Air Force Base Hospital | D2: 100 | E2: 100 | I2: 100 | J2: 100 | U2: 100 | V2: 87.5 | AB2: 68 | AC2: 58 | AD2: 42 | AE2: 43 | AG2: 61 | AH2: 47 | AI2: 73 | AK2: 42 | AN2: 46 | AO2: 55 | AP2: 27 | AQ2: 54 | AS2: 46 | AT2: 49 | AU2: 62 | AW2: 61 | AZ2: 69 | BA2: 75 | BB2: 112 | BC2: 167 | BE2: 206 | BF2: 219 | BG2: 89 | BI2: 179 | BL2: 42 | BM2: 30 | BN2: 36 | BO2: 92 | BS2: 62 | BU2: 86 | BX2: 19 | CE2: 57 | CG2: 73 | CK2: =ISNUMBER(D2) -> TRUE
A3: Abuja Municipal Area Council | B3: City Centre Ward | C3: 7 Guards Battalion Medical Reception Station Abuja | F3: 100 | G3: 100 | H3: 100 | I3: 100 | J3: 100 | K3: 100 | L3: 100 | M3: 100 | N3: 100 | O3: 75 | U3: 100 | V3: 100 | Z3: 100 | AD3: 6 | AE3: 10 | AF3: 11 | AG3: 12 | AH3: 8 | AI3: 8 | AJ3: 13 | AK3: 15 | AL3: 16 | AM3: 6 | AP3: 27 | AQ3: 14 | AR3: 8 | AS3: 13 | AT3: 10 | AU3: 9 | AV3: 16 | AW3: 13 | AX3: 8 | AY3: 5 | BB3: 38 | BC3: 16 | BD3: 1 | BF3: 6 | BG3: 9 | BH3: 14 | BI3: 9 | BJ3: 10 | BK3: 9 | BN3: 11 | BO3: 4 | BQ3: 2 | BU3: 8 | BV3: 8 | BW3: 12 | BZ3: 3 | CA3: 4 | CK3: =ISNUMBER(D3) -> FALSE
A4: Abaji Local Government Area | B4: Central (Abaji) Ward | C4: Abaji New Township Primary Health Center | E4: 100 | F4: 100 | G4: 100 | H4: 100 | I4: 200 | J4: 200 | K4: 150 | L4: 100 | M4: 100 | N4: 100 | O4: 100 | R4: 100 | S4: 100 | T4: 150 | U4: 200 | V4: 200 | X4: 50 | Z4: 100 | AA4: 100 | AC4: 28 | AD4: 15 | AE4: 15 | AF4: 20 | AG4: 16 | AH4: 11 | AI4: 17 | AJ4: 17 | AK4: 16 | AL4: 23 | AM4: 11 | AO4: 20 | AP4: 11 | AQ4: 21 | AR4: 18 | AS4: 16 | AT4: 24 | AU4: 16 | AV4: 16 | AW4: 11 | AX4: 17 | AY4: 12 | BA4: 12 | BB4: 30 | BC4: 30 | BD4: 19 | BE4: 37 | BF4: 53 | BG4: 46 | BH4: 33 | BI4: 21 | BJ4: 36 | BK4: 21 | BM4: 2 | BN4: 8 | BO4: 12 | BP4: 71 | BQ4: 7 | BR4: 6 | BS4: 11 | BT4: 18 | BU4: 22 | BV4: 22 | BW4: 11 | CB4: 1 | CE4: 1 | CK4: =ISNUMBER(D4) -> FALSE
A5: Abaji Local Government Area | B5: Central (Abaji) Ward | C5: Abaji Central Primary Health Clinic | E5: 40 | F5: 100 | G5: 100 | H5: 100 | I5: 100 | J5: 100 | K5: 100 | L5: 100 | M5: 100 | N5: 100 | O5: 100 | AC5: 8 | AD5: 4 | AE5: 9 | AF5: 8 | AG5: 6 | AH5: 8 | AI5: 6 | AJ5: 6 | AK5: 8 | AL5: 6 | AM5: 6 | AO5: 4 | AP5: 12 | AQ5: 12 | AR5: 5 | AS5: 8 | AT5: 11 | AU5: 6 | AV5: 5 | AW5: 6 | AX5: 6 | AY5: 8 | BB5: 7 | BD5: 12 | BE5: 6 | BF5: 5 | BG5: 2 | BH5: 7 | BI5: 6 | BJ5: 7 | BK5: 5 | BW5: 2 | CK5: =ISNUMBER(D5) -> FALSE
A6: Abaji Local Government Area | B6: North East Ward | C6: Abaji General Hospital | D6: 100 | E6: 100 | H6: 100 | M6: 100 | O6: 86.67 | P6: 33.33 | AB6: 51 | AC6: 117 | AD6: 117 | AE6: 87 | AF6: 101 | AJ6: 69 | AK6: 87 | AL6: 116 | AM6: 73 | AN6: 41 | AO6: 122 | AP6: 112 | AQ6: 94 | AR6: 94 | AV6: 67 | AW6: 82 | AX6: 59 | AY6: 69 | AZ6: 88 | BA6: 60 | BB6: 70 | BC6: 66 | BD6: 58 | BE6: 58 | BG6: 58 | BH6: 82 | BI6: 100 | BJ6: 62 | BK6: 73 | BL6: 48 | BM6: 64 | BN6: 52 | BO6: 46 | BP6: 46 | BQ6: 32 | BS6: 32 | BT6: 16 | BU6: 32 | BV6: 49 | BW6: 36 | BX6: 24 | BY6: 3 | BZ6: 28 | CA6: 20 | CB6: 20 | CC6: 10 | CE6: 10 | CF6: 2 | CG6: 2 | CH6: 9 | CI6: 4 | CK6: =ISNUMBER(D6) -> TRUE
A7: Abaji Local Government Area | B7: North East Ward | C7: Abaji Maternal And Child Health Clinic | E7: 60 | F7: 100 | G7: 100 | H7: 100 | I7: 100 | J7: 100 | K7: 80 | L7: 100 | M7: 100 | N7: 100 | O7: 75 | AC7: 7 | AD7: 14 | AE7: 19 | AF7: 28 | AG7: 18 | AH7: 19 | AI7: 17 | AJ7: 5 | AK7: 3 | AL7: 12 | AM7: 19 | AO7: 15 | AP7: 22 | AQ7: 12 | AR7: 16 | AS7: 13 | AT7: 22 | AU7: 10 | AV7: 15 | AW7: 34 | AX7: 6 | AY7: 6 | BA7: 3 | BB7: 3 | BE7: 3 | BF7: 1 | BG7: 3 | BH7: 4 | BK7: 11 | BR7: 1 | BS7: 1 | BT7: 2 | CE7: 1 | CF7: 1 | CG7: 7 | CK7: =ISNUMBER(D7) -> FALSE
A8: Abaji Local Government Area | B8: Nuku Sabon Gari Ward | C8: Abattior Primary Health Clinic | E8: 75 | F8: 100 | G8: 100 | H8: 100 | I8: 100 | J8: 100 | K8: 100 | L8: 100 | M8: 100 | N8: 100 | O8: 100 | S8: 50 | T8: 50 | U8: 100 | V8: 100 | W8: 100 | X8: 50 | Y8: 100 | Z8: 100 | AA8: 100 | AC8: 13 | AD8: 11 | AE8: 15 | AF8: 17 | AG8: 18 | AH8: 18 | AI8: 12 | AJ8: 16 | AK8: 28 | AL8: 37 | AM8: 22 | AO8: 5 | AP8: 5 | AQ8: 9 | AR8: 17 | AS8: 10 | AT8: 15 | AU8: 10 | AV8: 15 | AW8: 29 | AX8: 33 | AY8: 25 | BA8: 32 | BB8: 10 | BC8: 6 | BD8: 6 | BE8: 8 | BF8: 4 | BG8: 4 | BH8: 15 | BI8: 9 | BJ8: 7 | BK8: 20 | BN8: 1 | BP8: 3 | BQ8: 2 | BR8: 2 | BS8: 4 | BT8: 2 | BU8: 3 | BV8: 2 | BW8: 5 | CD8: 1 | CF8: 1 | CG8: 1 | CK8: =ISNUMBER(D8) -> FALSE
A9: Kwali Local Government Area | B9: Kwali Ward | C9: Abu Fatima Maternity Clinic | BA9: 7 | BC9: 30 | BD9: 6 | BF9: 3 | BG9: 1 | BH9: 2 | BL9: 11 | BM9: 5 | BO9: 15 | BP9: 5 | BR9: 2 | BU9: 9 | BV9: 6 | BX9: 11 | BY9: 5 | CA9: 15 | CB9: 5 | CE9: 7 | CG9: 9 | CK9: =ISNUMBER(D9) -> FALSE
A10: Abuja Municipal Area Council | B10: Garki Ward | C10: Abuja Clinic | AE10: 48 | AQ10: 24 | BC10: 10 | BO10: 2 | CA10: 6 | CK10: =ISNUMBER(D10) -> FALSE
A11: Abuja Municipal Area Council | B11: Wuse Ward | C11: Abuja Clinics, Maitama | O11: 100 | AF11: 10 | AI11: 30 | AK11: 8 | AM11: 27 | AR11: 25 | AU11: 20 | AW11: 5 | AY11: 32 | BG11: 30 | BI11: 25 | BS11: 6 | BU11: 24 | BW11: 46 | CE11: 8 | CI11: 14 | CK11: =ISNUMBER(D11) -> FALSE
A12: Abuja Municipal Area Council | B12: City Centre Ward | C12: Abuja Police Hospital | K12: 50 | L12: 50 | AI12: 34 | AJ12: 11 | AL12: 11 | AU12: 24 | AV12: 10 | AX12: 12 | BJ12: 10 | BS12: 11 | BT12: 8 | CE12: 36 | CF12: 40 | CK12: =ISNUMBER(D12) -> FALSE
A13: Kuje Local Government Area | B13: Kabi Ward | C13: Achimbi Primary Health Centre | E13: 100 | F13: 100 | G13: 100 | H13: 100 | I13: 100 | J13: 100 | K13: 100 | L13: 100 | M13: 100 | N13: 100 | O13: 100 | Q13: 100 | R13: 100 | S13: 100 | T13: 100 | U13: 100 | V13: 100 | W13: 100 | X13: 100 | Y13: 100 | Z13: 100 | AA13: 100 | AC13: 82 | AD13: 12 | AE13: 12 | AF13: 5 | AG13: 12 | AH13: 10 | AI13: 10 | AJ13: 24 | AK13: 6 | AL13: 26 | AM13: 19 | AO13: 91 | AP13: 11 | AQ13: 13 | AR13: 8 | AS13: 15 | AT13: 11 | AU13: 12 | AV13: 38 | AW13: 17 | AX13: 32 | AY13: 26 | BA13: 15 | BB13: 3 | BC13: 34 | BD13: 13 | BE13: 5 | BF13: 3 | BG13: 5 | BH13: 2 | BI13: 3 | BJ13: 7 | BK13: 7 | BN13: 1 | BO13: 3 | BP13: 2 | BQ13: 2 | BR13: 1 | BS13: 1 | BV13: 1 | BW13: 3 | CC13: 1 | CK13: =ISNUMBER(D13) -> FALSE
A14: Abaji Local Government Area | B14: Yaba Ward | C14: Adagba Primary Health Clinic | E14: 100 | F14: 100 | G14: 100 | H14: 100 | I14: 100 | J14: 50 | K14: 75 | M14: 100 | N14: 100 | O14: 100 | Q14: 83.33 | R14: 83.33 | S14: 100 | T14: 100 | U14: 100 | V14: 100 | W14: 100 | X14: 100 | Y14: 100 | Z14: 100 | AA14: 100 | AC14: 32 | AD14: 30 | AE14: 44 | AF14: 62 | AG14: 33 | AH14: 46 | AI14: 30 | AJ14: 52 | AK14: 44 | AL14: 45 | AM14: 43 | AO14: 36 | AP14: 43 | AQ14: 35 | AR14: 35 | AS14: 35 | AT14: 34 | AU14: 34 | AV14: 45 | AW14: 42 | AX14: 43 | AY14: 35 | BA14: 14 | BB14: 11 | BC14: 7 | BD14: 11 | BE14: 12 | BF14: 6 | BG14: 9 | BI14: 11 | BJ14: 14 | BK14: 20 | BV14: 3 | BW14: 2 | CK14: =ISNUMBER(D14) -> FALSE
A15: Kuje Local Government Area | B15: Kuje Central Ward | C15: Agape Biomedical Hospital | BC15: 1 | BF15: 1 | BG15: 1 | BI15: 1 | BR15: 1 | BS15: 1 | BT15: 1 | BU15: 4 | CE15: 1 | CK15: =ISNUMBER(D15) -> FALSE
A16: Kuje Local Government Area | B16: Kabi Ward | C16: Agwai Primary Health Centre | E16: 100 | F16: 100 | G16: 100 | H16: 100 | I16: 100 | J16: 100 | K16: 100 | L16: 100 | M16: 100 | N16: 100 | Q16: 100 | R16: 100 | S16: 100 | T16: 100 | V16: 100 | W16: 100 | X16: 100 | Y16: 80 | Z16: 100 | AC16: 93 | AD16: 32 | AE16: 14 | AF16: 6 | AG16: 7 | AH16: 9 | AI16: 10 | AJ16: 12 | AK16: 10 | AL16: 18 | AM16: 15 | AO16: 36 | AP16: 40 | AQ16: 28 | AR16: 9 | AS16: 16 | AT16: 24 | AU16: 10 | AV16: 16 | AW16: 21 | AX16: 26 | BB16: 2 | BC16: 1 | BD16: 8 | BE16: 1 | BF16: 1 | BG16: 3 | BH16: 4 | BK16: 14 | BR16: 1 | BW16: 3 | CK16: =ISNUMBER(D16) -> FALSE
A17: Abaji Local Government Area | B17: Pandagi Agyana Ward | C17: Agyana Primary Health Clinic | E17: 100 | F17: 100 | G17: 100 | H17: 100 | I17: 100 | J17: 100 | K17: 100 | L17: 100 | M17: 100 | N17: 100 | O17: 100 | Q17: 100 | R17: 100 | S17: 100 | T17: 100 | U17: 100 | V17: 100 | W17: 100 | X17: 100 | Y17: 100 | Z17: 100 | AA17: 100 | AC17: 31 | AD17: 36 | AE17: 16 | AF17: 46 | AG17: 24 | AH17: 45 | AI17: 31 | AJ17: 26 | AK17: 44 | AL17: 18 | AM17: 30 | AO17: 15 | AP17: 23 | AQ17: 52 | AR17: 55 | AS17: 17 | AT17: 51 | AU17: 32 | AV17: 30 | AW17: 37 | AX17: 31 | AY17: 49 | BA17: 2 | BB17: 14 | BC17: 5 | BD17: 10 | BE17: 7 | BF17: 13 | BG17: 12 | BH17: 12 | BI17: 4 | BJ17: 16 | BK17: 7 | BN17: 1 | BO17: 1 | BP17: 1 | BQ17: 5 | BS17: 4 | BU17: 5 | BW17: 2 | BY17: 15 | CC17: 30 | CD17: 13 | CK17: =ISNUMBER(D17) -> FALSE
A18: Abuja Municipal Area Council | B18: Gui Ward | C18: Al-Nur Maternity Home (Iddo-Pada) | AZ18: 10 | BA18: 12 | BB18: 3 | BC18: 2 | BD18: 1 | BE18: 5 | BF18: 5 | BG18: 5 | BH18: 4 | BI18: 2 | BJ18: 6 | BL18: 11 | BM18: 12 | BN18: 9 | BO18: 5 | BP18: 1 | BR18: 2 | BS18: 7 | BT18: 3 | BU18: 5 | BX18: 6 | BY18: 8 | BZ18: 3 | CB18: 5 | CC18: 1 | CD18: 1 | CF18: 2 | CG18: 1 | CH18: 4 | CK18: =ISNUMBER(D18) -> FALSE
A19: Abuja Municipal Area Council | B19: Kabusa Ward | C19: Aleiyita Primary Health Care Centre | E19: 100 | F19: 100 | H19: 100 | I19: 100 | J19: 100 | L19: 100 | M19: 100 | N19: 100 | O19: 100 | X19: 75 | AB19: 2 | AC19: 28 | AD19: 13 | AE19: 23 | AF19: 20 | AG19: 23 | AH19: 35 | AI19: 18 | AJ19: 17 | AK19: 22 | AL19: 21 | AM19: 22 | AN19: 3 | AO19: 42 | AP19: 22 | AQ19: 24 | AR19: 25 | AS19: 27 | AT19: 33 | AU19: 28 | AV19: 28 | AW19: 32 | AX19: 29 | AY19: 23 | BA19: 20 | BB19: 39 | BC19: 20 | BD19: 31 | BE19: 22 | BF19: 33 | BG19: 31 | BH19: 20 | BI19: 11 | BJ19: 15 | BK19: 22 | BN19: 2 | BO19: 12 | BP19: 6 | BQ19: 12 | BR19: 14 | BS19: 9 | BT19: 9 | BU19: 9 | BV19: 12 | BW19: 5 | CB19: 1 | CC19: 1 | CD19: 1 | CG19: 1 | CK19: =ISNUMBER(D19) -> FALSE
A20: Kuje Local Government Area | B20: Kuje Central Ward | C20: Alfad Specialist Clinic | BB20: 2 | BD20: 1 | BI20: 1 | BU20: 2 | CG20: 3 | CK20: =ISNUMBER(D20) -> FALSE
A21: Abuja Municipal Area Council | B21: City Centre Ward | C21: Alliance Clinic | D21: 100 | F21: 100 | G21: 100 | H21: 100 | I21: 100 | J21: 100 | K21: 100 | L21: 100 | M21: 100 | N21: 100 | AB21: 9 | AD21: 25 | AE21: 38 | AF21: 17 | AG21: 16 | AH21: 17 | AI21: 9 | AJ21: 20 | AK21: 21 | AL21: 11 | AM21: 9 | AN21: 8 | AP21: 21 | AQ21: 35 | AR21: 19 | AS21: 14 | AT21: 6 | AU21: 8 | AV21: 10 | AW21: 19 | AX21: 14 | AY21: 18 | AZ21: 11 | BB21: 12 | BC21: 10 | BD21: 18 | BE21: 14 | BF21: 10 | BG21: 3 | BH21: 25 | BI21: 25 | BJ21: 21 | BK21: 9 | BL21: 9 | BN21: 15 | BO21: 20 | BP21: 5 | BQ21: 8 | BR21: 14 | BS21: 7 | BT21: 20 | BV21: 6 | BW21: 8 | BX21: 10 | BZ21: 7 | CA21: 10 | CB21: 7 | CC21: 4 | CD21: 4 | CE21: 4 | CF21: 10 | CH21: 7 | CI21: 14 | CK21: =ISNUMBER(D21) -> TRUE
A22: Gwagwalada Local Government Area | B22: Quarters Ward | C22: Allied Specialist Hospital and Diagnostic Center Ltd Gwagwalada | AJ22: 2 | AL22: 2 | AV22: 2 | AX22: 2 | BG22: 15 | BH22: 12 | BJ22: 12 | BS22: 5 | BT22: 2 | BV22: 2 | CE22: 7 | CF22: 10 | CH22: 10 | CK22: =ISNUMBER(D22) -> FALSE
A23: Kuje Local Government Area | B23: Chibiri Ward | C23: Allison Clinic and Maternity | BA23: 6 | BB23: 10 | BC23: 6 | BD23: 4 | BG23: 12 | BH23: 4 | BI23: 6 | BJ23: 5 | BM23: 1 | BN23: 2 | BO23: 6 | BP23: 2 | BS23: 4 | BT23: 6 | BU23: 2 | BY23: 6 | CA23: 2 | CB23: 2 | CE23: 5 | CF23: 4 | CK23: =ISNUMBER(D23) -> FALSE
A24: Abaji Local Government Area | B24: Gawu Ward | C24: Almadinatu-Nibrass Primary Health Clinic | E24: 100 | G24: 100 | H24: 100 | I24: 100 | J24: 100 | K24: 100 | L24: 100 | M24: 100 | N24: 100 | O24: 100 | AC24: 8 | AE24: 11 | AF24: 11 | AG24: 10 | AH24: 11 | AI24: 9 | AJ24: 12 | AK24: 20 | AL24: 14 | AM24: 14 | AO24: 12 | AQ24: 9 | AR24: 12 | AS24: 11 | AT24: 13 | AU24: 9 | AV24: 11 | AW24: 17 | AX24: 11 | AY24: 11 | BA24: 3 | BC24: 5 | BD24: 9 | BF24: 11 | BG24: 14 | BH24: 10 | BI24: 9 | BJ24: 10 | BM24: 2 | BO24: 2 | BQ24: 3 | BR24: 2 | BS24: 2 | BT24: 3 | BU24: 1 | BV24: 3 | BW24: 4 | CK24: =ISNUMBER(D24) -> FALSE
A25: Abuja Municipal Area Council | B25: Karu Ward | C25: Alpha Clinic | BE25: 4 | BG25: 3 | BI25: 1 | BN25: 3 | BS25: 1 | BU25: 3 | CG25: 1 | CK25: =ISNUMBER(D25) -> FALSE
A26: Gwagwalada Local Government Area | B26: Tungan Maje Ward | C26: Anagada Health Clinic | E26: 50 | G26: 100 | H26: 100 | I26: 100 | J26: 100 | K26: 100 | L26: 62.5 | N26: 100 | O26: 100 | AA26: 100 | AC26: 97 | AE26: 46 | AF26: 45 | AG26: 55 | AH26: 43 | AI26: 34 | AJ26: 23 | AL26: 35 | AM26: 68 | AO26: 560 | AQ26: 59 | AR26: 48 | AS26: 34 | AT26: 41 | AU26: 33 | AV26: 36 | AX26: 30 | AY26: 61 | BC26: 10 | BD26: 24 | BE26: 9 | BF26: 25 | BG26: 18 | BH26: 15 | BJ26: 15 | BK26: 19 | BQ26: 7 | BS26: 11 | BT26: 8 | BV26: 14 | BW26: 4 | CD26: 2 | CK26: =ISNUMBER(D26) -> FALSE
A27: Gwagwalada Local Government Area | B27: Central Ward | C27: Anguwa Dodo Primary Health Centre | E27: 37.5 | F27: 100 | G27: 100 | H27: 100 | I27: 100 | J27: 100 | K27: 100 | L27: 100 | M27: 100 | N27: 100 | O27: 100 | W27: 100 | AA27: 100 | AC27: 33 | AD27: 29 | AE27: 46 | AF27: 43 | AG27: 45 | AH27: 52 | AI27: 25 | AJ27: 30 | AK27: 26 | AL27: 34 | AM27: 94 | AO27: 1107 | AP27: 17 | AQ27: 30 | AR27: 43 | AS27: 41 | AT27: 25 | AU27: 34 | AV27: 35 | AW27: 36 | AX27: 23 | AY27: 72 | BA27: 9 | BB27: 10 | BC27: 18 | BD27: 16 | BE27: 11 | BF27: 13 | BG27: 10 | BH27: 11 | BI27: 11 | BJ27: 20 | BK27: 10 | BO27: 2 | BP27: 2 | BQ27: 1 | BR27: 5 | BS27: 2 | BT27: 3 | BU27: 8 | BV27: 2 | BW27: 9 | CC27: 1 | CF27: 3 | CH27: 2 | CI27: 1 | CK27: =ISNUMBER(D27) -> FALSE
A28: Abuja Municipal Area Council | B28: Garki Ward | C28: Apo Primary Health Centre | E28: 50 | F28: 112.5 | G28: 100 | H28: 100 | I28: 100 | J28: 100 | K28: 87.5 | L28: 62.5 | M28: 225 | N28: 112.5 | O28: 100 | Q28: 116.67 | R28: 100 | S28: 75 | T28: 100 | U28: 75 | V28: 100 | W28: 125 | X28: 225 | Y28: 225 | Z28: 300 | AA28: 300 | AC28: 100 | AD28: 78 | AE28: 74 | AF28: 91 | AG28: 106 | AH28: 95 | AI28: 72 | AJ28: 75 | AK28: 118 | AL28: 155 | AM28: 92 | AO28: 74 | AP28: 78 | AQ28: 90 | AR28: 99 | AS28: 94 | AT28: 102 | AU28: 108 | AV28: 90 | AW28: 147 | AX28: 122 | AY28: 94 | BA28: 19 | BB28: 19 | BC28: 26 | BD28: 27 | BE28: 27 | BF28: 20 | BG28: 12 | BH28: 11 | BI28: 9 | BJ28: 20 | BK28: 17 | BO28: 3 | BP28: 3 | BQ28: 6 | BR28: 5 | BS28: 8 | BT28: 5 | BU28: 6 | BV28: 3 | BW28: 8 | CD28: 1 | CH28: 1 | CI28: 3 | CK28: =ISNUMBER(D28) -> FALSE
A29: Abuja Municipal Area Council | B29: Karu Ward | C29: Arewa Clinic and Maternity | AE29: 14 | AQ29: 13 | BC29: 75 | BO29: 20 | CA29: 15 | CK29: =ISNUMBER(D29) -> FALSE
A30: Gwagwalada Local Government Area | B30: Ibwa Ward | C30: Army Barrack Health Centre | D30: 100 | E30: 100 | F30: 100 | G30: 100 | H30: 100 | I30: 100 | J30: 100 | S30: 100 | T30: 100 | U30: 100 | V30: 100 | Z30: 100 | AB30: 18 | AC30: 56 | AD30: 8 | AE30: 15 | AF30: 10 | AG30: 16 | AH30: 12 | AN30: 12 | AO30: 384 | AQ30: 15 | AR30: 8 | AS30: 13 | AT30: 13 | AX30: 11 | AZ30: 7 | BA30: 5 | BB30: 5 | BC30: 8 | BD30: 12 | BE30: 6 | BF30: 8 | BJ30: 12 | BL30: 6 | BM30: 7 | BN30: 7 | BO30: 4 | BP30: 4 | BQ30: 6 | BR30: 11 | BV30: 5 | BY30: 2 | BZ30: 1 | CB30: 8 | CC30: 1 | CH30: 1 | CK30: =ISNUMBER(D30) -> TRUE
A31: Kwali Local Government Area | B31: Ashara Ward | C31: Ashara Basic Health Clinic | E31: 50 | F31: 100 | G31: 100 | H31: 100 | I31: 100 | J31: 100 | K31: 100 | L31: 75 | M31: 100 | N31: 100 | O31: 100 | R31: 100 | S31: 100 | T31: 100 | U31: 100 | V31: 100 | W31: 100 | X31: 75 | Y31: 75 | Z31: 100 | AA31: 100 | AC31: 35 | AD31: 38 | AE31: 9 | AF31: 36 | AG31: 38 | AH31: 40 | AI31: 29 | AJ31: 30 | AK31: 44 | AL31: 136 | AM31: 16 | AO31: 75 | AP31: 35 | AQ31: 5 | AR31: 31 | AS31: 36 | AT31: 38 | AU31: 28 | AV31: 22 | AW31: 32 | AX31: 105 | AY31: 28 | BA31: 4 | BB31: 8 | BC31: 7 | BD31: 19 | BE31: 21 | BF31: 15 | BG31: 10 | BH31: 20 | BI31: 21 | BJ31: 21 | BK31: 23 | BO31: 4 | BR31: 1 | CK31: =ISNUMBER(D31) -> FALSE
A32: Abuja Municipal Area Council | B32: City Centre Ward | C32: Asokoro General Hospital | E32: 100 | F32: 95.24 | G32: 95.24 | J32: 85.71 | K32: 95.24 | L32: 100 | M32: 95.24 | N32: 85.71 | O32: 100 | AB32: 185 | AC32: 143 | AD32: 122 | AE32: 112 | AH32: 95 | AI32: 62 | AJ32: 63 | AK32: 74 | AL32: 97 | AM32: 82 | AN32: 157 | AO32: 160 | AP32: 138 | AQ32: 115 | AT32: 75 | AU32: 96 | AV32: 96 | AW32: 70 | AX32: 92 | AY32: 73 | BB32: 144 | BC32: 75 | BF32: 65 | BG32: 84 | BH32: 96 | BI32: 116 | BJ32: 145 | BN32: 64 | BO32: 26 | BT32: 29 | BU32: 80 | BZ32: 16 | CA32: 11 | CF32: 25 | CG32: 42 | CK32: =ISNUMBER(D32) -> FALSE
A33: Bwari Local Government Area | B33: Dutse Ward | C33: Aujo Clinic and Maternity | BC33: 3 | BD33: 3 | BE33: 3 | BF33: 5 | BJ33: 5 | BK33: 3 | BO33: 1 | BP33: 4 | BQ33: 2 | BV33: 2 | BW33: 4 | CC33: 1 | CK33: =ISNUMBER(D33) -> FALSE
A34: Abaji Local Government Area | B34: North East Ward | C34: Ayaura Primary Health Centre | E34: 100 | F34: 100 | G34: 100 | H34: 100 | I34: 100 | J34: 100 | K34: 100 | L34: 100 | M34: 100 | N34: 100 | O34: 100 | Q34: 25 | R34: 100 | S34: 100 | T34: 100 | U34: 100 | V34: 100 | W34: 80 | X34: 100 | Y34: 100 | Z34: 100 | AA34: 100 | AC34: 34 | AD34: 31 | AE34: 34 | AF34: 38 | AG34: 40 | AH34: 48 | AI34: 40 | AJ34: 37 | AK34: 30 | AL34: 29 | AM34: 32 | AO34: 30 | AP34: 33 | AQ34: 36 | AR34: 34 | AS34: 31 | AT34: 45 | AU34: 41 | AV34: 47 | AW34: 43 | AX34: 39 | AY34: 32 | BA34: 54 | BB34: 24 | BC34: 24 | BD34: 57 | BE34: 28 | BF34: 36 | BG34: 52 | BH34: 34 | BI34: 31 | BJ34: 40 | BK34: 22 | BM34: 24 | BN34: 24 | BO34: 26 | BP34: 17 | BQ34: 10 | BR34: 16 | BS34: 14 | BT34: 26 | BU34: 26 | BV34: 18 | BW34: 11 | CA34: 2 | CC34: 2 | CD34: 2 | CE34: 2 | CG34: 1 | CH34: 5 | CI34: 2 | CK34: =ISNUMBER(D34) -> FALSE
A35: Kwali Local Government Area | B35: Pai Ward | C35: Bako Health Clinic | E35: 60 | F35: 100 | G35: 100 | H35: 100 | I35: 100 | J35: 100 | K35: 75 | L35: 50 | M35: 100 | N35: 100 | O35: 100 | R35: 100 | S35: 100 | T35: 100 | U35: 100 | V35: 100 | W35: 100 | X35: 50 | Y35: 100 | Z35: 100 | AA35: 100 | AC35: 60 | AD35: 23 | AE35: 23 | AF35: 36 | AG35: 30 | AH35: 28 | AI35: 23 | AJ35: 15 | AK35: 24 | AL35: 26 | AM35: 37 | AO35: 59 | AP35: 21 | AQ35: 22 | AR35: 35 | AS35: 28 | AT35: 26 | AU35: 21 | AV35: 13 | AW35: 22 | AX35: 24 | AY35: 35 | BA35: 6 | BB35: 1 | BC35: 4 | BD35: 2 | BE35: 8 | BF35: 10 | BG35: 4 | BH35: 2 | BI35: 2 | BJ35: 1 | BK35: 10 | BV35: 1 | BW35: 1 | CK35: =ISNUMBER(D35) -> FALSE
A36: Kwali Local Government Area | B36: Pai Ward | C36: Bako Wisdom Clinic and Maternity Home | AZ36: 7 | BA36: 8 | BB36: 2 | BC36: 2 | BF36: 2 | BG36: 10 | BH36: 10 | BI36: 10 | BJ36: 6 | BK36: 6 | BL36: 1 | BP36: 1 | BQ36: 1 | BV36: 3 | BW36: 3 | CK36: =ISNUMBER(D36) -> FALSE
A37: Bwari Local Government Area | B37: Bwari Central Ward | C37: Barangoni Primariy Health Clinic | E37: 50 | F37: 100 | H37: 100 | I37: 75 | J37: 100 | K37: 87.5 | L37: 100 | M37: 50 | N37: 100 | O37: 100 | Q37: 100 | S37: 100 | T37: 100 | U37: 250 | Y37: 300 | AA37: 100 | AC37: 20 | AD37: 20 | AE37: 55 | AF37: 38 | AG37: 17 | AH37: 10 | AI37: 15 | AJ37: 22 | AK37: 19 | AL37: 11 | AM37: 22 | AO37: 20 | AP37: 32 | AQ37: 38 | AR37: 31 | AS37: 5 | AT37: 19 | AU37: 23 | AV37: 19 | AW37: 17 | AX37: 15 | AY37: 11 | BA37: 28 | BB37: 7 | BC37: 10 | BD37: 6 | BE37: 6 | BF37: 12 | BG37: 14 | BH37: 11 | BI37: 18 | BJ37: 10 | BK37: 14 | BO37: 3 | BQ37: 6 | BR37: 1 | BS37: 2 | BT37: 1 | BU37: 2 | BV37: 5 | BW37: 2 | CB37: 25 | CK37: =ISNUMBER(D37) -> FALSE
A38: Abaji Local Government Area | B38: Gurdi Ward | C38: Bari-Bari Primary Health Clinic | H38: 100 | I38: 33.33 | J38: 100 | K38: 100 | L38: 100 | M38: 100 | N38: 100 | O38: 100 | T38: 100 | U38: 66.67 | V38: 100 | W38: 100 | X38: 100 | Y38: 100 | Z38: 100 | AA38: 100 | AC38: 35 | AD38: 29 | AE38: 21 | AF38: 25 | AG38: 20 | AH38: 20 | AI38: 11 | AJ38: 20 | AK38: 16 | AL38: 20 | AM38: 18 | AO38: 58 | AP38: 28 | AQ38: 27 | AR38: 24 | AS38: 17 | AT38: 16 | AU38: 14 | AV38: 26 | AW38: 15 | AX38: 22 | AY38: 14 | BD38: 26 | BE38: 18 | BG38: 8 | BH38: 24 | BI38: 9 | BJ38: 50 | BP38: 4 | BQ38: 13 | BR38: 11 | BS38: 4 | BT38: 15 | BV38: 10 | CB38: 6 | CC38: 7 | CD38: 6 | CF38: 7 | CG38: 46 | CK38: =ISNUMBER(D38) -> FALSE
A39: Abuja Municipal Area Council | B39: Jiwa Ward | C39: Bassan Jiwan Primary Health Care Centre | E39: 60 | F39: 100 | G39: 100 | H39: 100 | I39: 100 | J39: 100 | K39: 100 | L39: 100 | M39: 100 | N39: 100 | O39: 75 | S39: 50 | T39: 25 | U39: 75 | V39: 50 | X39: 75 | Y39: 75 | AC39: 88 | AD39: 28 | AE39: 37 | AF39: 48 | AG39: 62 | AH39: 51 | AI39: 23 | AJ39: 56 | AK39: 80 | AL39: 51 | AM39: 23 | AO39: 78 | AP39: 30 | AQ39: 37 | AR39: 38 | AS39: 47 | AT39: 53 | AU39: 35 | AV39: 59 | AW39: 36 | AX39: 44 | AY39: 38 | BA39: 9 | BB39: 54 | BC39: 37 | BD39: 25 | BE39: 5 | BF39: 7 | BG39: 14 | BH39: 20 | BI39: 17 | BJ39: 20 | BK39: 7 | BN39: 3 | BO39: 6 | BP39: 13 | BQ39: 5 | BR39: 9 | BS39: 9 | BT39: 11 | BU39: 8 | BV39: 14 | BW39: 4 | CA39: 2 | CE39: 1 | CF39: 3 | CG39: 7 | CH39: 7 | CI39: 3 | CK39: =ISNUMBER(D39) -> FALSE
A40: Abuja Municipal Area Council | B40: City Centre Ward | C40: Bepos Clinic and Fertility Centre | AF40: 18 | AG40: 23 | AH40: 20 | AI40: 18 | AJ40: 22 | AK40: 22 | AR40: 14 | AS40: 19 | AT40: 14 | AU40: 15 | AV40: 17 | AW40: 20 | BD40: 1 | BG40: 1 | BH40: 1 | BP40: 4 | BQ40: 4 | BR40: 5 | BS40: 10 | BU40: 5 | CB40: 2 | CC40: 2 | CD40: 5 | CE40: 5 | CG40: 3 | CK40: =ISNUMBER(D40) -> FALSE
...

Sheet Data_Quality_Assessment
A1: Area Council | B1: Ward | C1: Facility | D1: Reported Values | E1: Missing Values | F1: Expected Values | G1: Completeness (%) | H1: Completeness Rating | I1: Completeness Score | J1: Duplicate Facility Name | K1: Missing Critical Data | L1: Data Quality Status
A2: =TRIM(SUBSTITUTE(CLEAN(Raw_Data!A2),CHAR(160)," ")) -> Abuja Municipal Area Council | B2: {=TRIM(SUBSTITUTE(CLEAN(Raw_Data!B2),CHAR(160)," "))} -> Gui Ward | C2: {=TRIM(SUBSTITUTE(CLEAN(Raw_Data!C2),CHAR(160)," "))} -> 063 Nigeria Air Force Base Hospital | D2: =COUNTA(Raw_Data!D2:CI2) -> 39 | E2: =F2-D2 -> 45 | F2: =INDEX(tblParameters[Value],MATCH("ExpectedValues",tblParameters[Parameter],0)) -> 84 | G2: =D2/F2 -> 0.46428571 | H2: =LOOKUP(G2,tblIndicatorScore[Min],tblIndicatorScore[Rating]) -> Poor | I2: =LOOKUP(G2,tblIndicatorScore[Min],tblIndicatorScore[Score]) -> 0 | J2: =IF(OR(A2="",B2="",C2=""),"",IF(COUNTIFS($A:$A,A2,$B:$B,B2,$C:$C,C2)>1,"Yes","No")) -> No | K2: =IF(OR(TRIM(A2)="",TRIM(B2)="",TRIM(C2)="",D2<=0,F2<=0),"Yes","No") -> No | L2: =IFERROR( IF(K2="Yes","Incomplete", IF(OR( J2="Yes", G2<INDEX(tblParameters[Value],MATCH("MinimumAcceptCompleteness",tblParameters[Parameter],0)) ), "Review", "Accept")), "Parameter Error") -> Review
A3: =TRIM(SUBSTITUTE(CLEAN(Raw_Data!A3),CHAR(160)," ")) -> Abuja Municipal Area Council | B3: {=TRIM(SUBSTITUTE(CLEAN(Raw_Data!B3),CHAR(160)," "))} -> City Centre Ward | C3: {=TRIM(SUBSTITUTE(CLEAN(Raw_Data!C3),CHAR(160)," "))} -> 7 Guards Battalion Medical Reception Station Abuja | D3: =COUNTA(Raw_Data!D3:CI3) -> 50 | E3: =F3-D3 -> 34 | F3: =INDEX(tblParameters[Value],MATCH("ExpectedValues",tblParameters[Parameter],0)) -> 84 | G3: =D3/F3 -> 0.5952381 | H3: =LOOKUP(G3,tblIndicatorScore[Min],tblIndicatorScore[Rating]) -> Poor | I3: =LOOKUP(G3,tblIndicatorScore[Min],tblIndicatorScore[Score]) -> 0 | J3: =IF(OR(A3="",B3="",C3=""),"",IF(COUNTIFS($A:$A,A3,$B:$B,B3,$C:$C,C3)>1,"Yes","No")) -> No | K3: =IF(OR(TRIM(A3)="",TRIM(B3)="",TRIM(C3)="",D3<=0,F3<=0),"Yes","No") -> No | L3: =IFERROR( IF(K3="Yes","Incomplete", IF(OR( J3="Yes", G3<INDEX(tblParameters[Value],MATCH("MinimumAcceptCompleteness",tblParameters[Parameter],0)) ), "Review", "Accept")), "Parameter Error") -> Review
A4: =TRIM(SUBSTITUTE(CLEAN(Raw_Data!A4),CHAR(160)," ")) -> Abaji Local Government Area | B4: {=TRIM(SUBSTITUTE(CLEAN(Raw_Data!B4),CHAR(160)," "))} -> Central (Abaji) Ward | C4: {=TRIM(SUBSTITUTE(CLEAN(Raw_Data!C4),CHAR(160)," "))} -> Abaji New Township Primary Health Center | D4: =COUNTA(Raw_Data!D4:CI4) -> 65 | E4: =F4-D4 -> 19 | F4: =INDEX(tblParameters[Value],MATCH("ExpectedValues",tblParameters[Parameter],0)) -> 84 | G4: =D4/F4 -> 0.77380952 | H4: =LOOKUP(G4,tblIndicatorScore[Min],tblIndicatorScore[Rating]) -> Poor | I4: =LOOKUP(G4,tblIndicatorScore[Min],tblIndicatorScore[Score]) -> 0 | J4: =IF(OR(A4="",B4="",C4=""),"",IF(COUNTIFS($A:$A,A4,$B:$B,B4,$C:$C,C4)>1,"Yes","No")) -> No | K4: =IF(OR(TRIM(A4)="",TRIM(B4)="",TRIM(C4)="",D4<=0,F4<=0),"Yes","No") -> No | L4: =IFERROR( IF(K4="Yes","Incomplete", IF(OR( J4="Yes", G4<INDEX(tblParameters[Value],MATCH("MinimumAcceptCompleteness",tblParameters[Parameter],0)) ), "Review", "Accept")), "Parameter Error") -> Review
A5: =TRIM(SUBSTITUTE(CLEAN(Raw_Data!A5),CHAR(160)," ")) -> Abaji Local Government Area | B5: {=TRIM(SUBSTITUTE(CLEAN(Raw_Data!B5),CHAR(160)," "))} -> Central (Abaji) Ward | C5: {=TRIM(SUBSTITUTE(CLEAN(Raw_Data!C5),CHAR(160)," "))} -> Abaji Central Primary Health Clinic | D5: =COUNTA(Raw_Data!D5:CI5) -> 43 | E5: =F5-D5 -> 41 | F5: =INDEX(tblParameters[Value],MATCH("ExpectedValues",tblParameters[Parameter],0)) -> 84 | G5: =D5/F5 -> 0.51190476 | H5: =LOOKUP(G5,tblIndicatorScore[Min],tblIndicatorScore[Rating]) -> Poor | I5: =LOOKUP(G5,tblIndicatorScore[Min],tblIndicatorScore[Score]) -> 0 | J5: =IF(OR(A5="",B5="",C5=""),"",IF(COUNTIFS($A:$A,A5,$B:$B,B5,$C:$C,C5)>1,"Yes","No")) -> No | K5: =IF(OR(TRIM(A5)="",TRIM(B5)="",TRIM(C5)="",D5<=0,F5<=0),"Yes","No") -> No | L5: =IFERROR( IF(K5="Yes","Incomplete", IF(OR( J5="Yes", G5<INDEX(tblParameters[Value],MATCH("MinimumAcceptCompleteness",tblParameters[Parameter],0)) ), "Review", "Accept")), "Parameter Error") -> Review
A6: =TRIM(SUBSTITUTE(CLEAN(Raw_Data!A6),CHAR(160)," ")) -> Abaji Local Government Area | B6: {=TRIM(SUBSTITUTE(CLEAN(Raw_Data!B6),CHAR(160)," "))} -> North East Ward | C6: {=TRIM(SUBSTITUTE(CLEAN(Raw_Data!C6),CHAR(160)," "))} -> Abaji General Hospital | D6: =COUNTA(Raw_Data!D6:CI6) -> 57 | E6: =F6-D6 -> 27 | F6: =INDEX(tblParameters[Value],MATCH("ExpectedValues",tblParameters[Parameter],0)) -> 84 | G6: =D6/F6 -> 0.67857143 | H6: =LOOKUP(G6,tblIndicatorScore[Min],tblIndicatorScore[Rating]) -> Poor | I6: =LOOKUP(G6,tblIndicatorScore[Min],tblIndicatorScore[Score]) -> 0 | J6: =IF(OR(A6="",B6="",C6=""),"",IF(COUNTIFS($A:$A,A6,$B:$B,B6,$C:$C,C6)>1,"Yes","No")) -> No | K6: =IF(OR(TRIM(A6)="",TRIM(B6)="",TRIM(C6)="",D6<=0,F6<=0),"Yes","No") -> No | L6: =IFERROR( IF(K6="Yes","Incomplete", IF(OR( J6="Yes", G6<INDEX(tblParameters[Value],MATCH("MinimumAcceptCompleteness",tblParameters[Parameter],0)) ), "Review", "Accept")), "Parameter Error") -> Review
A7: =TRIM(SUBSTITUTE(CLEAN(Raw_Data!A7),CHAR(160)," ")) -> Abaji Local Government Area | B7: {=TRIM(SUBSTITUTE(CLEAN(Raw_Data!B7),CHAR(160)," "))} -> North East Ward | C7: {=TRIM(SUBSTITUTE(CLEAN(Raw_Data!C7),CHAR(160)," "))} -> Abaji Maternal And Child Health Clinic | D7: =COUNTA(Raw_Data!D7:CI7) -> 46 | E7: =F7-D7 -> 38 | F7: =INDEX(tblParameters[Value],MATCH("ExpectedValues",tblParameters[Parameter],0)) -> 84 | G7: =D7/F7 -> 0.54761905 | H7: =LOOKUP(G7,tblIndicatorScore[Min],tblIndicatorScore[Rating]) -> Poor | I7: =LOOKUP(G7,tblIndicatorScore[Min],tblIndicatorScore[Score]) -> 0 | J7: =IF(OR(A7="",B7="",C7=""),"",IF(COUNTIFS($A:$A,A7,$B:$B,B7,$C:$C,C7)>1,"Yes","No")) -> No | K7: =IF(OR(TRIM(A7)="",TRIM(B7)="",TRIM(C7)="",D7<=0,F7<=0),"Yes","No") -> No | L7: =IFERROR( IF(K7="Yes","Incomplete", IF(OR( J7="Yes", G7<INDEX(tblParameters[Value],MATCH("MinimumAcceptCompleteness",tblParameters[Parameter],0)) ), "Review", "Accept")), "Parameter Error") -> Review
A8: =TRIM(SUBSTITUTE(CLEAN(Raw_Data!A8),CHAR(160)," ")) -> Abaji Local Government Area | B8: {=TRIM(SUBSTITUTE(CLEAN(Raw_Data!B8),CHAR(160)," "))} -> Nuku Sabon Gari Ward | C8: {=TRIM(SUBSTITUTE(CLEAN(Raw_Data!C8),CHAR(160)," "))} -> Abattior Primary Health Clinic | D8: =COUNTA(Raw_Data!D8:CI8) -> 65 | E8: =F8-D8 -> 19 | F8: =INDEX(tblParameters[Value],MATCH("ExpectedValues",tblParameters[Parameter],0)) -> 84 | G8: =D8/F8 -> 0.77380952 | H8: =LOOKUP(G8,tblIndicatorScore[Min],tblIndicatorScore[Rating]) -> Poor | I8: =LOOKUP(G8,tblIndicatorScore[Min],tblIndicatorScore[Score]) -> 0 | J8: =IF(OR(A8="",B8="",C8=""),"",IF(COUNTIFS($A:$A,A8,$B:$B,B8,$C:$C,C8)>1,"Yes","No")) -> No | K8: =IF(OR(TRIM(A8)="",TRIM(B8)="",TRIM(C8)="",D8<=0,F8<=0),"Yes","No") -> No | L8: =IFERROR( IF(K8="Yes","Incomplete", IF(OR( J8="Yes", G8<INDEX(tblParameters[Value],MATCH("MinimumAcceptCompleteness",tblParameters[Parameter],0)) ), "Review", "Accept")), "Parameter Error") -> Review
A9: =TRIM(SUBSTITUTE(CLEAN(Raw_Data!A9),CHAR(160)," ")) -> Kwali Local Government Area | B9: {=TRIM(SUBSTITUTE(CLEAN(Raw_Data!B9),CHAR(160)," "))} -> Kwali Ward | C9: {=TRIM(SUBSTITUTE(CLEAN(Raw_Data!C9),CHAR(160)," "))} -> Abu Fatima Maternity Clinic | D9: =COUNTA(Raw_Data!D9:CI9) -> 19 | E9: =F9-D9 -> 65 | F9: =INDEX(tblParameters[Value],MATCH("ExpectedValues",tblParameters[Parameter],0)) -> 84 | G9: =D9/F9 -> 0.22619048 | H9: =LOOKUP(G9,tblIndicatorScore[Min],tblIndicatorScore[Rating]) -> Poor | I9: =LOOKUP(G9,tblIndicatorScore[Min],tblIndicatorScore[Score]) -> 0 | J9: =IF(OR(A9="",B9="",C9=""),"",IF(COUNTIFS($A:$A,A9,$B:$B,B9,$C:$C,C9)>1,"Yes","No")) -> No | K9: =IF(OR(TRIM(A9)="",TRIM(B9)="",TRIM(C9)="",D9<=0,F9<=0),"Yes","No") -> No | L9: =IFERROR( IF(K9="Yes","Incomplete", IF(OR( J9="Yes", G9<INDEX(tblParameters[Value],MATCH("MinimumAcceptCompleteness",tblParameters[Parameter],0)) ), "Review", "Accept")), "Parameter Error") -> Review
A10: =TRIM(SUBSTITUTE(CLEAN(Raw_Data!A10),CHAR(160)," ")) -> Abuja Municipal Area Council | B10: {=TRIM(SUBSTITUTE(CLEAN(Raw_Data!B10),CHAR(160)," "))} -> Garki Ward | C10: {=TRIM(SUBSTITUTE(CLEAN(Raw_Data!C10),CHAR(160)," "))} -> Abuja Clinic | D10: =COUNTA(Raw_Data!D10:CI10) -> 5 | E10: =F10-D10 -> 79 | F10: =INDEX(tblParameters[Value],MATCH("ExpectedValues",tblParameters[Parameter],0)) -> 84 | G10: =D10/F10 -> 0.05952381 | H10: =LOOKUP(G10,tblIndicatorScore[Min],tblIndicatorScore[Rating]) -> Poor | I10: =LOOKUP(G10,tblIndicatorScore[Min],tblIndicatorScore[Score]) -> 0 | J10: =IF(OR(A10="",B10="",C10=""),"",IF(COUNTIFS($A:$A,A10,$B:$B,B10,$C:$C,C10)>1,"Yes","No")) -> No | K10: =IF(OR(TRIM(A10)="",TRIM(B10)="",TRIM(C10)="",D10<=0,F10<=0),"Yes","No") -> No | L10: =IFERROR( IF(K10="Yes","Incomplete", IF(OR( J10="Yes", G10<INDEX(tblParameters[Value],MATCH("MinimumAcceptCompleteness",tblParameters[Parameter],0)) ), "Review", "Accept")), "Parameter Error") -> Review
A11: =TRIM(SUBSTITUTE(CLEAN(Raw_Data!A11),CHAR(160)," ")) -> Abuja Municipal Area Council | B11: {=TRIM(SUBSTITUTE(CLEAN(Raw_Data!B11),CHAR(160)," "))} -> Wuse Ward | C11: {=TRIM(SUBSTITUTE(CLEAN(Raw_Data!C11),CHAR(160)," "))} -> Abuja Clinics, Maitama | D11: =COUNTA(Raw_Data!D11:CI11) -> 16 | E11: =F11-D11 -> 68 | F11: =INDEX(tblParameters[Value],MATCH("ExpectedValues",tblParameters[Parameter],0)) -> 84 | G11: =D11/F11 -> 0.19047619 | H11: =LOOKUP(G11,tblIndicatorScore[Min],tblIndicatorScore[Rating]) -> Poor | I11: =LOOKUP(G11,tblIndicatorScore[Min],tblIndicatorScore[Score]) -> 0 | J11: =IF(OR(A11="",B11="",C11=""),"",IF(COUNTIFS($A:$A,A11,$B:$B,B11,$C:$C,C11)>1,"Yes","No")) -> No | K11: =IF(OR(TRIM(A11)="",TRIM(B11)="",TRIM(C11)="",D11<=0,F11<=0),"Yes","No") -> No | L11: =IFERROR( IF(K11="Yes","Incomplete", IF(OR( J11="Yes", G11<INDEX(tblParameters[Value],MATCH("MinimumAcceptCompleteness",tblParameters[Parameter],0)) ), "Review", "Accept")), "Parameter Error") -> Review
A12: =TRIM(SUBSTITUTE(CLEAN(Raw_Data!A12),CHAR(160)," ")) -> Abuja Municipal Area Council | B12: {=TRIM(SUBSTITUTE(CLEAN(Raw_Data!B12),CHAR(160)," "))} -> City Centre Ward | C12: {=TRIM(SUBSTITUTE(CLEAN(Raw_Data!C12),CHAR(160)," "))} -> Abuja Police Hospital | D12: =COUNTA(Raw_Data!D12:CI12) -> 13 | E12: =F12-D12 -> 71 | F12: =INDEX(tblParameters[Value],MATCH("ExpectedValues",tblParameters[Parameter],0)) -> 84 | G12: =D12/F12 -> 0.1547619 | H12: =LOOKUP(G12,tblIndicatorScore[Min],tblIndicatorScore[Rating]) -> Poor | I12: =LOOKUP(G12,tblIndicatorScore[Min],tblIndicatorScore[Score]) -> 0 | J12: =IF(OR(A12="",B12="",C12=""),"",IF(COUNTIFS($A:$A,A12,$B:$B,B12,$C:$C,C12)>1,"Yes","No")) -> No | K12: =IF(OR(TRIM(A12)="",TRIM(B12)="",TRIM(C12)="",D12<=0,F12<=0),"Yes","No") -> No | L12: =IFERROR( IF(K12="Yes","Incomplete", IF(OR( J12="Yes", G12<INDEX(tblParameters[Value],MATCH("MinimumAcceptCompleteness",tblParameters[Parameter],0)) ), "Review", "Accept")), "Parameter Error") -> Review
A13: =TRIM(SUBSTITUTE(CLEAN(Raw_Data!A13),CHAR(160)," ")) -> Kuje Local Government Area | B13: {=TRIM(SUBSTITUTE(CLEAN(Raw_Data!B13),CHAR(160)," "))} -> Kabi Ward | C13: {=TRIM(SUBSTITUTE(CLEAN(Raw_Data!C13),CHAR(160)," "))} -> Achimbi Primary Health Centre | D13: =COUNTA(Raw_Data!D13:CI13) -> 64 | E13: =F13-D13 -> 20 | F13: =INDEX(tblParameters[Value],MATCH("ExpectedValues",tblParameters[Parameter],0)) -> 84 | G13: =D13/F13 -> 0.76190476 | H13: =LOOKUP(G13,tblIndicatorScore[Min],tblIndicatorScore[Rating]) -> Poor | I13: =LOOKUP(G13,tblIndicatorScore[Min],tblIndicatorScore[Score]) -> 0 | J13: =IF(OR(A13="",B13="",C13=""),"",IF(COUNTIFS($A:$A,A13,$B:$B,B13,$C:$C,C13)>1,"Yes","No")) -> No | K13: =IF(OR(TRIM(A13)="",TRIM(B13)="",TRIM(C13)="",D13<=0,F13<=0),"Yes","No") -> No | L13: =IFERROR( IF(K13="Yes","Incomplete", IF(OR( J13="Yes", G13<INDEX(tblParameters[Value],MATCH("MinimumAcceptCompleteness",tblParameters[Parameter],0)) ), "Review", "Accept")), "Parameter Error") -> Review
... A398: =TRIM(SUBSTITUTE(CLEAN(Raw_Data!A398),CHAR(160)," ")) -> Gwagwalada Local Government Area | B398: {=TRIM(SUBSTITUTE(CLEAN(Raw_Data!B398),CHAR(160)," "))} -> Zuba Ward | C398: {=TRIM(SUBSTITUTE(CLEAN(Raw_Data!C398),CHAR(160)," "))} -> Zuba Primary Health Center | D398: =COUNTA(Raw_Data!D398:CI398) -> 62 | E398: =F398-D398 -> 22 | F398: =INDEX(tblParameters[Value],MATCH("ExpectedValues",tblParameters[Parameter],0)) -> 84 | G398: =D398/F398 -> 0.73809524 | H398: =LOOKUP(G398,tblIndicatorScore[Min],tblIndicatorScore[Rating]) -> Poor | I398: =LOOKUP(G398,tblIndicatorScore[Min],tblIndicatorScore[Score]) -> 0 | J398: =IF(OR(A398="",B398="",C398=""),"",IF(COUNTIFS($A:$A,A398,$B:$B,B398,$C:$C,C398)>1,"Yes","No")) -> No | K398: =IF(OR(TRIM(A398)="",TRIM(B398)="",TRIM(C398)="",D398<=0,F398<=0),"Yes","No") -> No | L398: =IFERROR( IF(K398="Yes","Incomplete", IF(OR( J398="Yes", G398<INDEX(tblParameters[Value],MATCH("MinimumAcceptCompleteness",tblParameters[Parameter],0)) ), "Review", "Accept")), "Parameter Error") -> Review

Sheet Derived_Indicators
A1: Area Council | B1: Ward | C1: Facility | D1: Avg Fixed Session (%) | E1: Avg Outreach Session (%) | F1: Total Penta1 | G1: Total Penta3 | H1: Total ANC1 | I1: Total ANC4 | J1: Total ANC8 | K1: Penta Completion (%) | L1: Penta Dropout (%) | M1: ANC4 Completion (%) | N1: ANC8 Completion (%) | O1: Penta Validity Status | P1: ANC Validity Status | Q1: Overall Validation Status
A2: =IF(Raw_Data!A2="","",TRIM(SUBSTITUTE(CLEAN(Raw_Data!A2),CHAR(160)," "))) -> Abuja Municipal Area Council | B2: =IF(Raw_Data!B2="","",TRIM(SUBSTITUTE(CLEAN(Raw_Data!B2),CHAR(160)," "))) -> Gui Ward | C2: =IF(Raw_Data!C2="","",TRIM(SUBSTITUTE(CLEAN(Raw_Data!C2),CHAR(160)," "))) -> 063 Nigeria Air Force Base Hospital | D2: =IFERROR(IF(COUNT(Raw_Data!D2:O2)=0,"",AVERAGE(Raw_Data!D2:O2)/100),"") -> 1 | E2: =IFERROR(IF(COUNT(Raw_Data!P2:AA2)=0,"",AVERAGE(Raw_Data!P2:AA2)/100),"") -> 0.9375 | F2: =IFERROR(IF(COUNT(Raw_Data!AB2:AM2)=0,"",SUM(Raw_Data!AB2:AM2)),"") -> 434 | G2: =IFERROR(IF(COUNT(Raw_Data!AN2:AY2)=0,"",SUM(Raw_Data!AN2:AY2)),"") -> 400 | H2: =IFERROR(IF(COUNT(Raw_Data!AZ2:BK2)=0,"",SUM(Raw_Data!AZ2:BK2)),"") -> 1116 | I2: =IFERROR(IF(COUNT(Raw_Data!BL2:BW2)=0,"",SUM(Raw_Data!BL2:BW2)),"") -> 348 | J2: =IFERROR(IF(COUNT(Raw_Data!BX2:CI2)=0,"",SUM(Raw_Data!BX2:CI2)),"") -> 149 | K2: =IFERROR(IF(OR(F2="",G2="",F2<=0),"",G2/F2),"") -> 0.92165899 | L2: =IFERROR(IF(OR(F2="",G2="",F2<=0),"",(F2-G2)/F2),"") -> 0.078341014 | M2: =IFERROR(IF(OR(H2="",I2="",H2<=0),"",I2/H2),"") -> 0.31182796 | N2: =IFERROR(IF(OR(H2="",J2="",H2<=0),"",J2/H2),"") -> 0.13351254 | O2: =IFERROR(IF(AND(F2="",G2=""),"No Data",IF(OR(F2="",G2="",F2<=0),"Incomplete",IF(OR(G2>F2,K2<0,K2>1,L2<0,L2>1),"Invalid","Valid"))),"Invalid") -> Valid | P2: =IFERROR(IF(AND(H2="",I2="",J2=""),"No Data",IF(OR(H2="",I2="",J2="",H2<=0),"Incomplete",IF(OR(I2>H2,J2>H2,J2>I2,M2<0,M2>1,N2<0,N2>1),"Invalid","Valid"))),"Invalid") -> Valid | Q2: =IF(OR(O2="No Data",P2="No Data"),"No Data",IF(OR(O2="Incomplete",P2="Incomplete"),"Incomplete",IF(OR(O2="Invalid",P2="Invalid"),"Invalid","Valid"))) -> Valid
A3: =IF(Raw_Data!A3="","",TRIM(SUBSTITUTE(CLEAN(Raw_Data!A3),CHAR(160)," "))) -> Abuja Municipal Area Council | B3: =IF(Raw_Data!B3="","",TRIM(SUBSTITUTE(CLEAN(Raw_Data!B3),CHAR(160)," "))) -> City Centre Ward | C3: =IF(Raw_Data!C3="","",TRIM(SUBSTITUTE(CLEAN(Raw_Data!C3),CHAR(160)," "))) -> 7 Guards Battalion Medical Reception Station Abuja | D3: =IFERROR(IF(COUNT(Raw_Data!D3:O3)=0,"",AVERAGE(Raw_Data!D3:O3)/100),"") -> 0.975 | E3: =IFERROR(IF(COUNT(Raw_Data!P3:AA3)=0,"",AVERAGE(Raw_Data!P3:AA3)/100),"") -> 1 | F3: =IFERROR(IF(COUNT(Raw_Data!AB3:AM3)=0,"",SUM(Raw_Data!AB3:AM3)),"") -> 105 | G3: =IFERROR(IF(COUNT(Raw_Data!AN3:AY3)=0,"",SUM(Raw_Data!AN3:AY3)),"") -> 123 | H3: =IFERROR(IF(COUNT(Raw_Data!AZ3:BK3)=0,"",SUM(Raw_Data!AZ3:BK3)),"") -> 112 | I3: =IFERROR(IF(COUNT(Raw_Data!BL3:BW3)=0,"",SUM(Raw_Data!BL3:BW3)),"") -> 45 | J3: =IFERROR(IF(COUNT(Raw_Data!BX3:CI3)=0,"",SUM(Raw_Data!BX3:CI3)),"") -> 7 | K3: =IFERROR(IF(OR(F3="",G3="",F3<=0),"",G3/F3),"") -> 1.1714286 | L3: =IFERROR(IF(OR(F3="",G3="",F3<=0),"",(F3-G3)/F3),"") -> -0.17142857 | M3: =IFERROR(IF(OR(H3="",I3="",H3<=0),"",I3/H3),"") -> 0.40178571 | N3: =IFERROR(IF(OR(H3="",J3="",H3<=0),"",J3/H3),"") -> 0.0625 | O3: =IFERROR(IF(AND(F3="",G3=""),"No Data",IF(OR(F3="",G3="",F3<=0),"Incomplete",IF(OR(G3>F3,K3<0,K3>1,L3<0,L3>1),"Invalid","Valid"))),"Invalid") -> Invalid | P3: =IFERROR(IF(AND(H3="",I3="",J3=""),"No Data",IF(OR(H3="",I3="",J3="",H3<=0),"Incomplete",IF(OR(I3>H3,J3>H3,J3>I3,M3<0,M3>1,N3<0,N3>1),"Invalid","Valid"))),"Invalid") -> Valid | Q3: =IF(OR(O3="No Data",P3="No Data"),"No Data",IF(OR(O3="Incomplete",P3="Incomplete"),"Incomplete",IF(OR(O3="Invalid",P3="Invalid"),"Invalid","Valid"))) -> Invalid
A4: =IF(Raw_Data!A4="","",TRIM(SUBSTITUTE(CLEAN(Raw_Data!A4),CHAR(160)," "))) -> Abaji Local Government Area | B4: =IF(Raw_Data!B4="","",TRIM(SUBSTITUTE(CLEAN(Raw_Data!B4),CHAR(160)," "))) -> Central (Abaji) Ward | C4: =IF(Raw_Data!C4="","",TRIM(SUBSTITUTE(CLEAN(Raw_Data!C4),CHAR(160)," "))) -> Abaji New Township Primary Health Center | D4: =IFERROR(IF(COUNT(Raw_Data!D4:O4)=0,"",AVERAGE(Raw_Data!D4:O4)/100),"") -> 1.2272727 | E4: =IFERROR(IF(COUNT(Raw_Data!P4:AA4)=0,"",AVERAGE(Raw_Data!P4:AA4)/100),"") -> 1.25 | F4: =IFERROR(IF(COUNT(Raw_Data!AB4:AM4)=0,"",SUM(Raw_Data!AB4:AM4)),"") -> 189 | G4: =IFERROR(IF(COUNT(Raw_Data!AN4:AY4)=0,"",SUM(Raw_Data!AN4:AY4)),"") -> 182 | H4: =IFERROR(IF(COUNT(Raw_Data!AZ4:BK4)=0,"",SUM(Raw_Data!AZ4:BK4)),"") -> 338 | I4: =IFERROR(IF(COUNT(Raw_Data!BL4:BW4)=0,"",SUM(Raw_Data!BL4:BW4)),"") -> 190 | J4: =IFERROR(IF(COUNT(Raw_Data!BX4:CI4)=0,"",SUM(Raw_Data!BX4:CI4)),"") -> 2 | K4: =IFERROR(IF(OR(F4="",G4="",F4<=0),"",G4/F4),"") -> 0.96296296 | L4: =IFERROR(IF(OR(F4="",G4="",F4<=0),"",(F4-G4)/F4),"") -> 0.037037037 | M4: =IFERROR(IF(OR(H4="",I4="",H4<=0),"",I4/H4),"") -> 0.56213018 | N4: =IFERROR(IF(OR(H4="",J4="",H4<=0),"",J4/H4),"") -> 0.0059171598 | O4: =IFERROR(IF(AND(F4="",G4=""),"No Data",IF(OR(F4="",G4="",F4<=0),"Incomplete",IF(OR(G4>F4,K4<0,K4>1,L4<0,L4>1),"Invalid","Valid"))),"Invalid") -> Valid | P4: =IFERROR(IF(AND(H4="",I4="",J4=""),"No Data",IF(OR(H4="",I4="",J4="",H4<=0),"Incomplete",IF(OR(I4>H4,J4>H4,J4>I4,M4<0,M4>1,N4<0,N4>1),"Invalid","Valid"))),"Invalid") -> Valid | Q4: =IF(OR(O4="No Data",P4="No Data"),"No Data",IF(OR(O4="Incomplete",P4="Incomplete"),"Incomplete",IF(OR(O4="Invalid",P4="Invalid"),"Invalid","Valid"))) -> Valid
A5: =IF(Raw_Data!A5="","",TRIM(SUBSTITUTE(CLEAN(Raw_Data!A5),CHAR(160)," "))) -> Abaji Local Government Area | B5: =IF(Raw_Data!B5="","",TRIM(SUBSTITUTE(CLEAN(Raw_Data!B5),CHAR(160)," "))) -> Central (Abaji) Ward | C5: =IF(Raw_Data!C5="","",TRIM(SUBSTITUTE(CLEAN(Raw_Data!C5),CHAR(160)," "))) -> Abaji Central Primary Health Clinic | D5: =IFERROR(IF(COUNT(Raw_Data!D5:O5)=0,"",AVERAGE(Raw_Data!D5:O5)/100),"") -> 0.94545455 | E5: =IFERROR(IF(COUNT(Raw_Data!P5:AA5)=0,"",AVERAGE(Raw_Data!P5:AA5)/100),"") | F5: =IFERROR(IF(COUNT(Raw_Data!AB5:AM5)=0,"",SUM(Raw_Data!AB5:AM5)),"") -> 75 | G5: =IFERROR(IF(COUNT(Raw_Data!AN5:AY5)=0,"",SUM(Raw_Data!AN5:AY5)),"") -> 83 | H5: =IFERROR(IF(COUNT(Raw_Data!AZ5:BK5)=0,"",SUM(Raw_Data!AZ5:BK5)),"") -> 57 | I5: =IFERROR(IF(COUNT(Raw_Data!BL5:BW5)=0,"",SUM(Raw_Data!BL5:BW5)),"") -> 2 | J5: =IFERROR(IF(COUNT(Raw_Data!BX5:CI5)=0,"",SUM(Raw_Data!BX5:CI5)),"") | K5: =IFERROR(IF(OR(F5="",G5="",F5<=0),"",G5/F5),"") -> 1.1066667 | L5: =IFERROR(IF(OR(F5="",G5="",F5<=0),"",(F5-G5)/F5),"") -> -0.10666667 | M5: =IFERROR(IF(OR(H5="",I5="",H5<=0),"",I5/H5),"") -> 0.035087719 | N5: =IFERROR(IF(OR(H5="",J5="",H5<=0),"",J5/H5),"") | O5: =IFERROR(IF(AND(F5="",G5=""),"No Data",IF(OR(F5="",G5="",F5<=0),"Incomplete",IF(OR(G5>F5,K5<0,K5>1,L5<0,L5>1),"Invalid","Valid"))),"Invalid") -> Invalid | P5: =IFERROR(IF(AND(H5="",I5="",J5=""),"No Data",IF(OR(H5="",I5="",J5="",H5<=0),"Incomplete",IF(OR(I5>H5,J5>H5,J5>I5,M5<0,M5>1,N5<0,N5>1),"Invalid","Valid"))),"Invalid") -> Incomplete | Q5: =IF(OR(O5="No Data",P5="No Data"),"No Data",IF(OR(O5="Incomplete",P5="Incomplete"),"Incomplete",IF(OR(O5="Invalid",P5="Invalid"),"Invalid","Valid"))) -> Incomplete
A6: =IF(Raw_Data!A6="","",TRIM(SUBSTITUTE(CLEAN(Raw_Data!A6),CHAR(160)," "))) -> Abaji Local Government Area | B6: =IF(Raw_Data!B6="","",TRIM(SUBSTITUTE(CLEAN(Raw_Data!B6),CHAR(160)," "))) -> North East Ward | C6: =IF(Raw_Data!C6="","",TRIM(SUBSTITUTE(CLEAN(Raw_Data!C6),CHAR(160)," "))) -> Abaji General Hospital | D6: =IFERROR(IF(COUNT(Raw_Data!D6:O6)=0,"",AVERAGE(Raw_Data!D6:O6)/100),"") -> 0.97334 | E6: =IFERROR(IF(COUNT(Raw_Data!P6:AA6)=0,"",AVERAGE(Raw_Data!P6:AA6)/100),"") -> 0.3333 | F6: =IFERROR(IF(COUNT(Raw_Data!AB6:AM6)=0,"",SUM(Raw_Data!AB6:AM6)),"") -> 818 | G6: =IFERROR(IF(COUNT(Raw_Data!AN6:AY6)=0,"",SUM(Raw_Data!AN6:AY6)),"") -> 740 | H6: =IFERROR(IF(COUNT(Raw_Data!AZ6:BK6)=0,"",SUM(Raw_Data!AZ6:BK6)),"") -> 775 | I6: =IFERROR(IF(COUNT(Raw_Data!BL6:BW6)=0,"",SUM(Raw_Data!BL6:BW6)),"") -> 453 | J6: =IFERROR(IF(COUNT(Raw_Data!BX6:CI6)=0,"",SUM(Raw_Data!BX6:CI6)),"") -> 132 | K6: =IFERROR(IF(OR(F6="",G6="",F6<=0),"",G6/F6),"") -> 0.90464548 | L6: =IFERROR(IF(OR(F6="",G6="",F6<=0),"",(F6-G6)/F6),"") -> 0.095354523 | M6: =IFERROR(IF(OR(H6="",I6="",H6<=0),"",I6/H6),"") -> 0.58451613 | N6: =IFERROR(IF(OR(H6="",J6="",H6<=0),"",J6/H6),"") -> 0.17032258 | O6: =IFERROR(IF(AND(F6="",G6=""),"No Data",IF(OR(F6="",G6="",F6<=0),"Incomplete",IF(OR(G6>F6,K6<0,K6>1,L6<0,L6>1),"Invalid","Valid"))),"Invalid") -> Valid | P6: =IFERROR(IF(AND(H6="",I6="",J6=""),"No Data",IF(OR(H6="",I6="",J6="",H6<=0),"Incomplete",IF(OR(I6>H6,J6>H6,J6>I6,M6<0,M6>1,N6<0,N6>1),"Invalid","Valid"))),"Invalid") -> Valid | Q6: =IF(OR(O6="No Data",P6="No Data"),"No Data",IF(OR(O6="Incomplete",P6="Incomplete"),"Incomplete",IF(OR(O6="Invalid",P6="Invalid"),"Invalid","Valid"))) -> Valid
A7: =IF(Raw_Data!A7="","",TRIM(SUBSTITUTE(CLEAN(Raw_Data!A7),CHAR(160)," "))) -> Abaji Local Government Area | B7: =IF(Raw_Data!B7="","",TRIM(SUBSTITUTE(CLEAN(Raw_Data!B7),CHAR(160)," "))) -> North East Ward | C7: =IF(Raw_Data!C7="","",TRIM(SUBSTITUTE(CLEAN(Raw_Data!C7),CHAR(160)," "))) -> Abaji Maternal And Child Health Clinic | D7: =IFERROR(IF(COUNT(Raw_Data!D7:O7)=0,"",AVERAGE(Raw_Data!D7:O7)/100),"") -> 0.92272727 | E7: =IFERROR(IF(COUNT(Raw_Data!P7:AA7)=0,"",AVERAGE(Raw_Data!P7:AA7)/100),"") | F7: =IFERROR(IF(COUNT(Raw_Data!AB7:AM7)=0,"",SUM(Raw_Data!AB7:AM7)),"") -> 161 | G7: =IFERROR(IF(COUNT(Raw_Data!AN7:AY7)=0,"",SUM(Raw_Data!AN7:AY7)),"") -> 171 | H7: =IFERROR(IF(COUNT(Raw_Data!AZ7:BK7)=0,"",SUM(Raw_Data!AZ7:BK7)),"") -> 28 | I7: =IFERROR(IF(COUNT(Raw_Data!BL7:BW7)=0,"",SUM(Raw_Data!BL7:BW7)),"") -> 4 | J7: =IFERROR(IF(COUNT(Raw_Data!BX7:CI7)=0,"",SUM(Raw_Data!BX7:CI7)),"") -> 9 | K7: =IFERROR(IF(OR(F7="",G7="",F7<=0),"",G7/F7),"") -> 1.0621118 | L7: =IFERROR(IF(OR(F7="",G7="",F7<=0),"",(F7-G7)/F7),"") -> -0.062111801 | M7: =IFERROR(IF(OR(H7="",I7="",H7<=0),"",I7/H7),"") -> 0.14285714 | N7: =IFERROR(IF(OR(H7="",J7="",H7<=0),"",J7/H7),"") -> 0.32142857 | O7: =IFERROR(IF(AND(F7="",G7=""),"No Data",IF(OR(F7="",G7="",F7<=0),"Incomplete",IF(OR(G7>F7,K7<0,K7>1,L7<0,L7>1),"Invalid","Valid"))),"Invalid") -> Invalid | P7: =IFERROR(IF(AND(H7="",I7="",J7=""),"No Data",IF(OR(H7="",I7="",J7="",H7<=0),"Incomplete",IF(OR(I7>H7,J7>H7,J7>I7,M7<0,M7>1,N7<0,N7>1),"Invalid","Valid"))),"Invalid") -> Invalid | Q7: =IF(OR(O7="No Data",P7="No Data"),"No Data",IF(OR(O7="Incomplete",P7="Incomplete"),"Incomplete",IF(OR(O7="Invalid",P7="Invalid"),"Invalid","Valid"))) -> Invalid
A8: =IF(Raw_Data!A8="","",TRIM(SUBSTITUTE(CLEAN(Raw_Data!A8),CHAR(160)," "))) -> Abaji Local Government Area | B8: =IF(Raw_Data!B8="","",TRIM(SUBSTITUTE(CLEAN(Raw_Data!B8),CHAR(160)," "))) -> Nuku Sabon Gari Ward | C8: =IF(Raw_Data!C8="","",TRIM(SUBSTITUTE(CLEAN(Raw_Data!C8),CHAR(160)," "))) -> Abattior Primary Health Clinic | D8: =IFERROR(IF(COUNT(Raw_Data!D8:O8)=0,"",AVERAGE(Raw_Data!D8:O8)/100),"") -> 0.97727273 | E8: =IFERROR(IF(COUNT(Raw_Data!P8:AA8)=0,"",AVERAGE(Raw_Data!P8:AA8)/100),"") -> 0.83333333 | F8: =IFERROR(IF(COUNT(Raw_Data!AB8:AM8)=0,"",SUM(Raw_Data!AB8:AM8)),"") -> 207 | G8: =IFERROR(IF(COUNT(Raw_Data!AN8:AY8)=0,"",SUM(Raw_Data!AN8:AY8)),"") -> 173 | H8: =IFERROR(IF(COUNT(Raw_Data!AZ8:BK8)=0,"",SUM(Raw_Data!AZ8:BK8)),"") -> 121 | I8: =IFERROR(IF(COUNT(Raw_Data!BL8:BW8)=0,"",SUM(Raw_Data!BL8:BW8)),"") -> 24 | J8: =IFERROR(IF(COUNT(Raw_Data!BX8:CI8)=0,"",SUM(Raw_Data!BX8:CI8)),"") -> 3 | K8: =IFERROR(IF(OR(F8="",G8="",F8<=0),"",G8/F8),"") -> 0.83574879 | L8: =IFERROR(IF(OR(F8="",G8="",F8<=0),"",(F8-G8)/F8),"") -> 0.16425121 | M8: =IFERROR(IF(OR(H8="",I8="",H8<=0),"",I8/H8),"") -> 0.19834711 | N8: =IFERROR(IF(OR(H8="",J8="",H8<=0),"",J8/H8),"") -> 0.024793388 | O8: =IFERROR(IF(AND(F8="",G8=""),"No Data",IF(OR(F8="",G8="",F8<=0),"Incomplete",IF(OR(G8>F8,K8<0,K8>1,L8<0,L8>1),"Invalid","Valid"))),"Invalid") -> Valid | P8: =IFERROR(IF(AND(H8="",I8="",J8=""),"No Data",IF(OR(H8="",I8="",J8="",H8<=0),"Incomplete",IF(OR(I8>H8,J8>H8,J8>I8,M8<0,M8>1,N8<0,N8>1),"Invalid","Valid"))),"Invalid") -> Valid | Q8: =IF(OR(O8="No Data",P8="No Data"),"No Data",IF(OR(O8="Incomplete",P8="Incomplete"),"Incomplete",IF(OR(O8="Invalid",P8="Invalid"),"Invalid","Valid"))) -> Valid
A9: =IF(Raw_Data!A9="","",TRIM(SUBSTITUTE(CLEAN(Raw_Data!A9),CHAR(160)," "))) -> Kwali Local Government Area | B9: =IF(Raw_Data!B9="","",TRIM(SUBSTITUTE(CLEAN(Raw_Data!B9),CHAR(160)," "))) -> Kwali Ward | C9: =IF(Raw_Data!C9="","",TRIM(SUBSTITUTE(CLEAN(Raw_Data!C9),CHAR(160)," "))) -> Abu Fatima Maternity Clinic | D9: =IFERROR(IF(COUNT(Raw_Data!D9:O9)=0,"",AVERAGE(Raw_Data!D9:O9)/100),"") | E9: =IFERROR(IF(COUNT(Raw_Data!P9:AA9)=0,"",AVERAGE(Raw_Data!P9:AA9)/100),"") | F9: =IFERROR(IF(COUNT(Raw_Data!AB9:AM9)=0,"",SUM(Raw_Data!AB9:AM9)),"") | G9: =IFERROR(IF(COUNT(Raw_Data!AN9:AY9)=0,"",SUM(Raw_Data!AN9:AY9)),"") | H9: =IFERROR(IF(COUNT(Raw_Data!AZ9:BK9)=0,"",SUM(Raw_Data!AZ9:BK9)),"") -> 49 | I9: =IFERROR(IF(COUNT(Raw_Data!BL9:BW9)=0,"",SUM(Raw_Data!BL9:BW9)),"") -> 53 | J9: =IFERROR(IF(COUNT(Raw_Data!BX9:CI9)=0,"",SUM(Raw_Data!BX9:CI9)),"") -> 52 | K9: =IFERROR(IF(OR(F9="",G9="",F9<=0),"",G9/F9),"") | L9: =IFERROR(IF(OR(F9="",G9="",F9<=0),"",(F9-G9)/F9),"") | M9: =IFERROR(IF(OR(H9="",I9="",H9<=0),"",I9/H9),"") -> 1.0816327 | N9: =IFERROR(IF(OR(H9="",J9="",H9<=0),"",J9/H9),"") -> 1.0612245 | O9: =IFERROR(IF(AND(F9="",G9=""),"No Data",IF(OR(F9="",G9="",F9<=0),"Incomplete",IF(OR(G9>F9,K9<0,K9>1,L9<0,L9>1),"Invalid","Valid"))),"Invalid") -> No Data | P9: =IFERROR(IF(AND(H9="",I9="",J9=""),"No Data",IF(OR(H9="",I9="",J9="",H9<=0),"Incomplete",IF(OR(I9>H9,J9>H9,J9>I9,M9<0,M9>1,N9<0,N9>1),"Invalid","Valid"))),"Invalid") -> Invalid | Q9: =IF(OR(O9="No Data",P9="No Data"),"No Data",IF(OR(O9="Incomplete",P9="Incomplete"),"Incomplete",IF(OR(O9="Invalid",P9="Invalid"),"Invalid","Valid"))) -> No Data
A10: =IF(Raw_Data!A10="","",TRIM(SUBSTITUTE(CLEAN(Raw_Data!A10),CHAR(160)," "))) -> Abuja Municipal Area Council | B10: =IF(Raw_Data!B10="","",TRIM(SUBSTITUTE(CLEAN(Raw_Data!B10),CHAR(160)," "))) -> Garki Ward | C10: =IF(Raw_Data!C10="","",TRIM(SUBSTITUTE(CLEAN(Raw_Data!C10),CHAR(160)," "))) -> Abuja Clinic | D10: =IFERROR(IF(COUNT(Raw_Data!D10:O10)=0,"",AVERAGE(Raw_Data!D10:O10)/100),"") | E10: =IFERROR(IF(COUNT(Raw_Data!P10:AA10)=0,"",AVERAGE(Raw_Data!P10:AA10)/100),"") | F10: =IFERROR(IF(COUNT(Raw_Data!AB10:AM10)=0,"",SUM(Raw_Data!AB10:AM10)),"") -> 48 | G10: =IFERROR(IF(COUNT(Raw_Data!AN10:AY10)=0,"",SUM(Raw_Data!AN10:AY10)),"") -> 24 | H10: =IFERROR(IF(COUNT(Raw_Data!AZ10:BK10)=0,"",SUM(Raw_Data!AZ10:BK10)),"") -> 10 | I10: =IFERROR(IF(COUNT(Raw_Data!BL10:BW10)=0,"",SUM(Raw_Data!BL10:BW10)),"") -> 2 | J10: =IFERROR(IF(COUNT(Raw_Data!BX10:CI10)=0,"",SUM(Raw_Data!BX10:CI10)),"") -> 6 | K10: =IFERROR(IF(OR(F10="",G10="",F10<=0),"",G10/F10),"") -> 0.5 | L10: =IFERROR(IF(OR(F10="",G10="",F10<=0),"",(F10-G10)/F10),"") -> 0.5 | M10: =IFERROR(IF(OR(H10="",I10="",H10<=0),"",I10/H10),"") -> 0.2 | N10: =IFERROR(IF(OR(H10="",J10="",H10<=0),"",J10/H10),"") -> 0.6 | O10: =IFERROR(IF(AND(F10="",G10=""),"No Data",IF(OR(F10="",G10="",F10<=0),"Incomplete",IF(OR(G10>F10,K10<0,K10>1,L10<0,L10>1),"Invalid","Valid"))),"Invalid") -> Valid | P10: =IFERROR(IF(AND(H10="",I10="",J10=""),"No Data",IF(OR(H10="",I10="",J10="",H10<=0),"Incomplete",IF(OR(I10>H10,J10>H10,J10>I10,M10<0,M10>1,N10<0,N10>1),"Invalid","Valid"))),"Invalid") -> Invalid | Q10: =IF(OR(O10="No Data",P10="No Data"),"No Data",IF(OR(O10="Incomplete",P10="Incomplete"),"Incomplete",IF(OR(O10="Invalid",P10="Invalid"),"Invalid","Valid"))) -> Invalid
A11: =IF(Raw_Data!A11="","",TRIM(SUBSTITUTE(CLEAN(Raw_Data!A11),CHAR(160)," "))) -> Abuja Municipal Area Council | B11: =IF(Raw_Data!B11="","",TRIM(SUBSTITUTE(CLEAN(Raw_Data!B11),CHAR(160)," "))) -> Wuse Ward | C11: =IF(Raw_Data!C11="","",TRIM(SUBSTITUTE(CLEAN(Raw_Data!C11),CHAR(160)," "))) -> Abuja Clinics, Maitama | D11: =IFERROR(IF(COUNT(Raw_Data!D11:O11)=0,"",AVERAGE(Raw_Data!D11:O11)/100),"") -> 1 | E11: =IFERROR(IF(COUNT(Raw_Data!P11:AA11)=0,"",AVERAGE(Raw_Data!P11:AA11)/100),"") | F11: =IFERROR(IF(COUNT(Raw_Data!AB11:AM11)=0,"",SUM(Raw_Data!AB11:AM11)),"") -> 75 | G11: =IFERROR(IF(COUNT(Raw_Data!AN11:AY11)=0,"",SUM(Raw_Data!AN11:AY11)),"") -> 82 | H11: =IFERROR(IF(COUNT(Raw_Data!AZ11:BK11)=0,"",SUM(Raw_Data!AZ11:BK11)),"") -> 55 | I11: =IFERROR(IF(COUNT(Raw_Data!BL11:BW11)=0,"",SUM(Raw_Data!BL11:BW11)),"") -> 76 | J11: =IFERROR(IF(COUNT(Raw_Data!BX11:CI11)=0,"",SUM(Raw_Data!BX11:CI11)),"") -> 22 | K11: =IFERROR(IF(OR(F11="",G11="",F11<=0),"",G11/F11),"") -> 1.0933333 | L11: =IFERROR(IF(OR(F11="",G11="",F11<=0),"",(F11-G11)/F11),"") -> -0.093333333 | M11: =IFERROR(IF(OR(H11="",I11="",H11<=0),"",I11/H11),"") -> 1.3818182 | N11: =IFERROR(IF(OR(H11="",J11="",H11<=0),"",J11/H11),"") -> 0.4 | O11: =IFERROR(IF(AND(F11="",G11=""),"No Data",IF(OR(F11="",G11="",F11<=0),"Incomplete",IF(OR(G11>F11,K11<0,K11>1,L11<0,L11>1),"Invalid","Valid"))),"Invalid") -> Invalid | P11: =IFERROR(IF(AND(H11="",I11="",J11=""),"No Data",IF(OR(H11="",I11="",J11="",H11<=0),"Incomplete",IF(OR(I11>H11,J11>H11,J11>I11,M11<0,M11>1,N11<0,N11>1),"Invalid","Valid"))),"Invalid") -> Invalid | Q11: =IF(OR(O11="No Data",P11="No Data"),"No Data",IF(OR(O11="Incomplete",P11="Incomplete"),"Incomplete",IF(OR(O11="Invalid",P11="Invalid"),"Invalid","Valid"))) -> Invalid
A12: =IF(Raw_Data!A12="","",TRIM(SUBSTITUTE(CLEAN(Raw_Data!A12),CHAR(160)," "))) -> Abuja Municipal Area Council | B12: =IF(Raw_Data!B12="","",TRIM(SUBSTITUTE(CLEAN(Raw_Data!B12),CHAR(160)," "))) -> City Centre Ward | C12: =IF(Raw_Data!C12="","",TRIM(SUBSTITUTE(CLEAN(Raw_Data!C12),CHAR(160)," "))) -> Abuja Police Hospital | D12: =IFERROR(IF(COUNT(Raw_Data!D12:O12)=0,"",AVERAGE(Raw_Data!D12:O12)/100),"") -> 0.5 | E12: =IFERROR(IF(COUNT(Raw_Data!P12:AA12)=0,"",AVERAGE(Raw_Data!P12:AA12)/100),"") | F12: =IFERROR(IF(COUNT(Raw_Data!AB12:AM12)=0,"",SUM(Raw_Data!AB12:AM12)),"") -> 56 | G12: =IFERROR(IF(COUNT(Raw_Data!AN12:AY12)=0,"",SUM(Raw_Data!AN12:AY12)),"") -> 46 | H12: =IFERROR(IF(COUNT(Raw_Data!AZ12:BK12)=0,"",SUM(Raw_Data!AZ12:BK12)),"") -> 10 | I12: =IFERROR(IF(COUNT(Raw_Data!BL12:BW12)=0,"",SUM(Raw_Data!BL12:BW12)),"") -> 19 | J12: =IFERROR(IF(COUNT(Raw_Data!BX12:CI12)=0,"",SUM(Raw_Data!BX12:CI12)),"") -> 76 | K12: =IFERROR(IF(OR(F12="",G12="",F12<=0),"",G12/F12),"") -> 0.82142857 | L12: =IFERROR(IF(OR(F12="",G12="",F12<=0),"",(F12-G12)/F12),"") -> 0.17857143 | M12: =IFERROR(IF(OR(H12="",I12="",H12<=0),"",I12/H12),"") -> 1.9 | N12: =IFERROR(IF(OR(H12="",J12="",H12<=0),"",J12/H12),"") -> 7.6 | O12: =IFERROR(IF(AND(F12="",G12=""),"No Data",IF(OR(F12="",G12="",F12<=0),"Incomplete",IF(OR(G12>F12,K12<0,K12>1,L12<0,L12>1),"Invalid","Valid"))),"Invalid") -> Valid | P12: =IFERROR(IF(AND(H12="",I12="",J12=""),"No Data",IF(OR(H12="",I12="",J12="",H12<=0),"Incomplete",IF(OR(I12>H12,J12>H12,J12>I12,M12<0,M12>1,N12<0,N12>1),"Invalid","Valid"))),"Invalid") -> Invalid | Q12: =IF(OR(O12="No Data",P12="No Data"),"No Data",IF(OR(O12="Incomplete",P12="Incomplete"),"Incomplete",IF(OR(O12="Invalid",P12="Invalid"),"Invalid","Valid"))) -> Invalid
A13: =IF(Raw_Data!A13="","",TRIM(SUBSTITUTE(CLEAN(Raw_Data!A13),CHAR(160)," "))) -> Kuje Local Government Area | B13: =IF(Raw_Data!B13="","",TRIM(SUBSTITUTE(CLEAN(Raw_Data!B13),CHAR(160)," "))) -> Kabi Ward | C13: =IF(Raw_Data!C13="","",TRIM(SUBSTITUTE(CLEAN(Raw_Data!C13),CHAR(160)," "))) -> Achimbi Primary Health Centre | D13: =IFERROR(IF(COUNT(Raw_Data!D13:O13)=0,"",AVERAGE(Raw_Data!D13:O13)/100),"") -> 1 | E13: =IFERROR(IF(COUNT(Raw_Data!P13:AA13)=0,"",AVERAGE(Raw_Data!P13:AA13)/100),"") -> 1 | F13: =IFERROR(IF(COUNT(Raw_Data!AB13:AM13)=0,"",SUM(Raw_Data!AB13:AM13)),"") -> 218 | G13: =IFERROR(IF(COUNT(Raw_Data!AN13:AY13)=0,"",SUM(Raw_Data!AN13:AY13)),"") -> 274 | H13: =IFERROR(IF(COUNT(Raw_Data!AZ13:BK13)=0,"",SUM(Raw_Data!AZ13:BK13)),"") -> 97 | I13: =IFERROR(IF(COUNT(Raw_Data!BL13:BW13)=0,"",SUM(Raw_Data!BL13:BW13)),"") -> 14 | J13: =IFERROR(IF(COUNT(Raw_Data!BX13:CI13)=0,"",SUM(Raw_Data!BX13:CI13)),"") -> 1 | K13: =IFERROR(IF(OR(F13="",G13="",F13<=0),"",G13/F13),"") -> 1.2568807 | L13: =IFERROR(IF(OR(F13="",G13="",F13<=0),"",(F13-G13)/F13),"") -> -0.25688073 | M13: =IFERROR(IF(OR(H13="",I13="",H13<=0),"",I13/H13),"") -> 0.1443299 | N13: =IFERROR(IF(OR(H13="",J13="",H13<=0),"",J13/H13),"") -> 0.010309278 | O13: =IFERROR(IF(AND(F13="",G13=""),"No Data",IF(OR(F13="",G13="",F13<=0),"Incomplete",IF(OR(G13>F13,K13<0,K13>1,L13<0,L13>1),"Invalid","Valid"))),"Invalid") -> Invalid | P13: =IFERROR(IF(AND(H13="",I13="",J13=""),"No Data",IF(OR(H13="",I13="",J13="",H13<=0),"Incomplete",IF(OR(I13>H13,J13>H13,J13>I13,M13<0,M13>1,N13<0,N13>1),"Invalid","Valid"))),"Invalid") -> Valid | Q13: =IF(OR(O13="No Data",P13="No Data"),"No Data",IF(OR(O13="Incomplete",P13="Incomplete"),"Incomplete",IF(OR(O13="Invalid",P13="Invalid"),"Invalid","Valid"))) -> Invalid
